input/input.txt
BUY LIMIT 100.0000 10
SELL LIMIT 101.0000 10
BUY LIMIT 100.5000 5
SELL LIMIT 100.5000 5
BUY LIMIT 99.0000 20
SELL LIMIT 99.0000 5
SELL LIMIT 99.0000 15
BUY LIMIT 98.5000 1
BUY LIMIT 98.5000 1
SELL LIMIT 98.5000 2
SELL LIMIT 105.0000 50
BUY LIMIT 105.0000 100
BUY LIMIT 102.0000 0.0001
SELL LIMIT 95.1234 10
BUY LIMIT 95.1235 10
